Workbook

Sheet AGP
B2: TEAM PENJUALAN AGP | K2: TEAM PENJUALAN DIVISI SALESMAN
B5: Month | C5: ALL AGP | H5: Growth | K5: Month | L5: TEAM PENJUALAN ( AGPs , AGPc , AGPN ) | T5: Growth
C6: 2024 | D6: 2025 | E6: TGT 2026 | F6: 2026 | G6: ACH | H6: 26 vs 24 | I6: 26 vs 25 | L6: 2024 | M6: 2025 | N6: 2026 | T6: 26 vs 24 | U6: 26 vs 25
B7: Jan | C7: =SUM(L8,C31,C53) -> 24159186786 | D7: =SUM(M8,D31,TELE!D8,D53) -> 21337690605 | E7: =SUM(N8,E31,TELE!E8,E53) -> 40920000000 | F7: =SUM(R8,F31,TELE!F8,F53) -> 2.5826447e+10 | G7: =IFERROR(F7/E7,0) -> 0.63114485 | H7: =IFERROR(F7/C7-1,0) -> 0.069011457 | I7: =IFERROR(F7/D7-1,0) -> 0.21036751 | N7: TGT | O7: AGPC | P7: AGPS | Q7: AGPN | R7: TOTAL | S7: ACH
B8: Feb | C8: =SUM(L9,C32,C54) -> 23396499193 | D8: =SUM(M9,D32,TELE!D9,D54) -> 26684172922 | E8: =SUM(N9,E32,TELE!E9,E54) -> 37800000000 | F8: =SUM(R9,F32,TELE!F9,F54) -> 2.6436475e+10 | G8: =IFERROR(F8/E8,0) -> 0.69937764 | H8: =IFERROR(F8/C8-1,0) -> 0.12993293 | I8: =IFERROR(F8/D8-1,0) -> -0.009282584 | K8: Jan | L8: =AGPN!D6+AGPc!D6+AGPs!D5 -> 22585261686 | M8: =AGPN!E6+AGPc!E6+AGPs!E5 -> 20342621421 | N8: =AGPN!F6+AGPc!F6+AGPs!F5 -> 36880000000 | O8: =AGPc!G6 -> 9.944665e+09 | P8: =AGPs!G5 -> 8.9014341e+09 | Q8: =AGPN!G6 -> 5016540388 | R8: =AGPN!G6+AGPc!G6+AGPs!G5 -> 2.386264e+10 | S8: =IFERROR(R8/N8,0) -> 0.6470347 | T8: =IFERROR(R8/L8-1,0) -> 0.056558029 | U8: =IFERROR(R8/M8-1,0) -> 0.1730366
B9: Mar | C9: =SUM(L10,C33,C55) -> 24938302602 | D9: =SUM(M10,D33,TELE!D10,D55) -> 22450328228 | E9: =SUM(N10,E33,TELE!E10,E55) -> 37800000000 | F9: =SUM(R10,F33,TELE!F10,F55) -> 1.3791552e+10 | G9: =IFERROR(F9/E9,0) -> 0.36485587 | H9: =IFERROR(F9/C9-1,0) -> -0.44697311 | I9: =IFERROR(F9/D9-1,0) -> -0.38568595 | K9: Feb | L9: =AGPN!D7+AGPc!D7+AGPs!D6 -> 21889752258 | M9: =AGPN!E7+AGPc!E7+AGPs!E6 -> 24547717344 | N9: =AGPN!F7+AGPc!F7+AGPs!F6 -> 33760000000 | O9: =AGPc!G7 -> 1.0890748e+10 | P9: =AGPs!G6 -> 8.1885422e+09 | Q9: =AGPN!G7 -> 5.0309831e+09 | R9: =AGPN!G7+AGPc!G7+AGPs!G6 -> 2.4110273e+10 | S9: =IFERROR(R9/N9,0) -> 0.71416686 | T9: =IFERROR(R9/L9-1,0) -> 0.10144111 | U9: =IFERROR(R9/M9-1,0) -> -0.017820161
B10: Apr | C10: =SUM(L11,C34,C56) -> 15761115621 | D10: =SUM(M11,D34,TELE!D11,D56) -> 21371627964 | E10: =SUM(N11,E34,TELE!E11,E56) -> 40380000000 | F10: =SUM(R11,F34,TELE!F11,F56) -> 2.5128711e+10 | G10: =IFERROR(F10/E10,0) -> 0.62230588 | H10: =IFERROR(F10/C10-1,0) -> 0.59434851 | I10: =IFERROR(F10/D10-1,0) -> 0.17579771 | K10: Mar | L10: =AGPN!D8+AGPc!D8+AGPs!D7 -> 22899608218 | M10: =AGPN!E8+AGPc!E8+AGPs!E7 -> 20716698521 | N10: =AGPN!F8+AGPc!F8+AGPs!F7 -> 33760000000 | O10: =AGPc!G8 -> 5.2715889e+09 | P10: =AGPs!G7 -> 4.5625521e+09 | Q10: =AGPN!G8 -> 2.3041601e+09 | R10: =AGPN!G8+AGPc!G8+AGPs!G7 -> 1.2138301e+10 | S10: =IFERROR(R10/N10,0) -> 0.35954683 | T10: =IFERROR(R10/L10-1,0) -> -0.46993411 | U10: =IFERROR(R10/M10-1,0) -> -0.4140813
B11: May | C11: =SUM(L12,C35,C57) -> 24487748149 | D11: =SUM(M12,D35,TELE!D12,D57) -> 26482379609 | E11: =SUM(N12,E35,TELE!E12,E57) -> 37260000000 | F11: =SUM(R12,F35,TELE!F12,F57) -> 2.1173631e+10 | G11: =IFERROR(F11/E11,0) -> 0.56826707 | H11: =IFERROR(F11/C11-1,0) -> -0.13533776 | I11: =IFERROR(F11/D11-1,0) -> -0.20046343 | K11: Apr | L11: =AGPN!D9+AGPc!D9+AGPs!D8 -> 14758281711 | M11: =AGPN!E9+AGPc!E9+AGPs!E8 -> 19831812491 | N11: =AGPN!F9+AGPc!F9+AGPs!F8 -> 36880000000 | O11: =AGPc!G9 -> 9.1031812e+09 | P11: =AGPs!G8 -> 8.8376468e+09 | Q11: =AGPN!G9 -> 4.8171723e+09 | R11: =AGPN!G9+AGPc!G9+AGPs!G8 -> 2.2758e+10 | S11: =IFERROR(R11/N11,0) -> 0.61708244 | T11: =IFERROR(R11/L11-1,0) -> 0.54204946 | U11: =IFERROR(R11/M11-1,0) -> 0.14755019
B12: Jun | C12: =SUM(L13,C36,C58) -> 28664608260 | D12: =SUM(M13,D36,TELE!D13,D58) -> 23629392392 | E12: =SUM(N13,E36,TELE!E13,E58) -> 37260000000 | F12: =SUM(R13,F36,TELE!F13,F58) -> 2.4014237e+10 | G12: =IFERROR(F12/E12,0) -> 0.64450449 | H12: =IFERROR(F12/C12-1,0) -> -0.1622339 | I12: =IFERROR(F12/D12-1,0) -> 0.016286697 | K12: May | L12: =AGPN!D10+AGPc!D10+AGPs!D9 -> 22730316307 | M12: =AGPN!E10+AGPc!E10+AGPs!E9 -> 24484721143 | N12: =AGPN!F10+AGPc!F10+AGPs!F9 -> 33760000000 | O12: =AGPc!G10 -> 9.594543e+09 | P12: =AGPs!G9 -> 6.1018458e+09 | Q12: =AGPN!G10 -> 3.2575439e+09 | R12: =AGPN!G10+AGPc!G10+AGPs!G9 -> 1.8953933e+10 | S12: =IFERROR(R12/N12,0) -> 0.56143166 | T12: =IFERROR(R12/L12-1,0) -> -0.16613863 | U12: =IFERROR(R12/M12-1,0) -> -0.22588734
B13: Sem1 | C13: =SUM(C7:C12) -> 141407460611 | D13: =SUM(D7:D12) -> 141955591720 | E13: =SUM(E7:E12) -> 231420000000 | F13: =SUM(F7:F12) -> 1.3637105e+11 | G13: =IFERROR(F13/E13,0) -> 0.58927947 | H13: =IFERROR(F13/C13-1,0) -> -0.035616273 | I13: =IFERROR(F13/D13-1,0) -> -0.039340035 | K13: Jun | L13: =AGPN!D11+AGPc!D11+AGPs!D10 -> 26527508857 | M13: =AGPN!E11+AGPc!E11+AGPs!E10 -> 22071306489 | N13: =AGPN!F11+AGPc!F11+AGPs!F10 -> 33760000000 | O13: =AGPc!G11 -> 9.6887769e+09 | P13: =AGPs!G10 -> 7.9828873e+09 | Q13: =AGPN!G11 -> 3.4437395e+09 | R13: =AGPN!G11+AGPc!G11+AGPs!G10 -> 2.1115404e+10 | S13: =IFERROR(R13/N13,0) -> 0.62545627 | T13: =IFERROR(R13/L13-1,0) -> -0.2040186 | U13: =IFERROR(R13/M13-1,0) -> -0.043309749
B14: Jul | C14: =SUM(L15,C38,C60) -> 25468635015 | D14: =SUM(M15,D38,TELE!D15,D60) -> 25871489943 | E14: =SUM(N15,E38,TELE!E15,E60) -> 37260000000 | F14: =SUM(R15,F38,TELE!F15,F60) -> 2.840798e+10 | G14: =IFERROR(F14/E14,0) -> 0.76242564 | H14: =IFERROR(F14/C14-1,0) -> 0.11541037 | I14: =IFERROR(F14/D14-1,0) -> 0.098041882 | K14: Sem1 | L14: =SUM(L8:L13) -> 131390729037 | M14: =SUM(M8:M13) -> 131994877409 | N14: =SUM(N8:N13) -> 208800000000 | O14: =SUM(O8:O13) -> 5.4493503e+10 | P14: =SUM(P8:P13) -> 4.4574908e+10 | Q14: =SUM(Q8:Q13) -> 2.3870139e+10 | R14: =SUM(R8:R13) -> 1.2293855e+11 | S14: =IFERROR(R14/N14,0) -> 0.58878616 | T14: =IFERROR(R14/L14-1,0) -> -0.064328576 | U14: =IFERROR(R14/M14-1,0) -> -0.0686112
A15: =(F15-F14)/F14 -> -0.19156412 | B15: Aug | C15: =SUM(L16,C39,C61) -> 26335746702 | D15: =SUM(M16,D39,TELE!D16,D61) -> 26006146126 | E15: =SUM(N16,E39,TELE!E16,E61) -> 40380000000 | F15: =SUM(R16,F39,TELE!F16,F61) -> 2.296603e+10 | G15: =IFERROR(F15/E15,0) -> 0.56874764 | H15: =IFERROR(F15/C15-1,0) -> -0.1279522 | I15: =IFERROR(F15/D15-1,0) -> -0.11689991 | K15: Jul | L15: =AGPN!D13+AGPc!D13+AGPs!D12 -> 23599006137 | M15: =AGPN!E13+AGPc!E13+AGPs!E12 -> 23901112453 | N15: =AGPN!F13+AGPc!F13+AGPs!F12 -> 33760000000 | O15: =AGPc!G13 -> 1.1441452e+10 | P15: =AGPs!G12 -> 9.4377576e+09 | Q15: =AGPN!G13 -> 4.926376e+09 | R15: =AGPN!G13+AGPc!G13+AGPs!G12 -> 2.5805586e+10 | S15: =IFERROR(R15/N15,0) -> 0.76438347 | T15: =IFERROR(R15/L15-1,0) -> 0.093503082 | U15: =IFERROR(R15/M15-1,0) -> 0.079681374
B16: Sep | C16: =SUM(L17,C40,C62) -> 25507315030 | D16: =SUM(M17,D40,TELE!D17,D62) -> 25955151907 | E16: =SUM(N17,E40,TELE!E17,E62) -> 37260000000 | F16: =SUM(R17,F40,TELE!F17,F62) -> 1.7829153e+10 | G16: =IFERROR(F16/E16,0) -> 0.47850653 | H16: =IFERROR(F16/C16-1,0) -> -0.30101803 | I16: =IFERROR(F16/D16-1,0) -> -0.31307845 | K16: Aug | L16: =AGPN!D14+AGPc!D14+AGPs!D13 -> 24281662045 | M16: =AGPN!E14+AGPc!E14+AGPs!E13 -> 23729834895 | N16: =AGPN!F14+AGPc!F14+AGPs!F13 -> 36880000000 | O16: =AGPc!G14 -> 1.0463408e+10 | P16: =AGPs!G13 -> 7.139499e+09 | Q16: =AGPN!G14 -> 3.659961e+09 | R16: =AGPN!G14+AGPc!G14+AGPs!G13 -> 2.1262868e+10 | S16: =IFERROR(R16/N16,0) -> 0.57654197 | T16: =IFERROR(R16/L16-1,0) -> -0.12432404 | U16: =IFERROR(R16/M16-1,0) -> -0.10396057 | W16: =(R16-R15)/R15 -> -0.17603623
B17: Oct | C17: =SUM(L18,C41,C63) -> 26172805118 | D17: =SUM(M18,D41,TELE!D18,D63) -> 25882344879 | E17: =SUM(N18,E41,TELE!E18,E63) -> 40380000000 | F17: =SUM(R18,F41,TELE!F18,F63) -> 0 | G17: =IFERROR(F17/E17,0) -> 0 | H17: =IFERROR(F17/C17-1,0) -> -1 | I17: =IFERROR(F17/D17-1,0) -> -1 | K17: Sep | L17: =AGPN!D15+AGPc!D15+AGPs!D14 -> 23356680661 | M17: =AGPN!E15+AGPc!E15+AGPs!E14 -> 23843988531 | N17: =AGPN!F15+AGPc!F15+AGPs!F14 -> 33760000000 | O17: =AGPc!G15 -> 7.7718034e+09 | P17: =AGPs!G14 -> 6.412417e+09 | Q17: =AGPN!G15 -> 3.0800791e+09 | R17: =AGPN!G15+AGPc!G15+AGPs!G14 -> 1.72643e+10 | S17: =IFERROR(R17/N17,0) -> 0.51138328 | T17: =IFERROR(R17/L17-1,0) -> -0.26084105 | U17: =IFERROR(R17/M17-1,0) -> -0.2759475
B18: Nov | C18: =SUM(L19,C42,C64) -> 24806895809 | D18: =SUM(M19,D42,TELE!D19,D64) -> 23982150334 | E18: =SUM(N19,E42,TELE!E19,E64) -> 37260000000 | F18: =SUM(R19,F42,TELE!F19,F64) -> 0 | G18: =IFERROR(F18/E18,0) -> 0 | H18: =IFERROR(F18/C18-1,0) -> -1 | I18: =IFERROR(F18/D18-1,0) -> -1 | K18: Oct | L18: =AGPN!D16+AGPc!D16+AGPs!D15 -> 24757990009 | M18: =AGPN!E16+AGPc!E16+AGPs!E15 -> 23392221486 | N18: =AGPN!F16+AGPc!F16+AGPs!F15 -> 36880000000 | O18: =AGPc!G16 -> 0 | P18: =AGPs!G15 -> 0 | Q18: =AGPN!G16 -> 0 | R18: =AGPN!G16+AGPc!G16+AGPs!G15 -> 0 | S18: =IFERROR(R18/N18,0) -> 0 | T18: =IFERROR(R18/L18-1,0) -> -1 | U18: =IFERROR(R18/M18-1,0) -> -1
B19: Dec | C19: =SUM(L20,C43,C65) -> 25551616179 | D19: =SUM(M20,D43,TELE!D20,D65) -> 26847129519 | E19: =SUM(N20,E43,TELE!E20,E65) -> 37260000000 | F19: =SUM(R20,F43,TELE!F20,F65) -> 0 | G19: =IFERROR(F19/E19,0) -> 0 | H19: =IFERROR(F19/C19-1,0) -> -1 | I19: =IFERROR(F19/D19-1,0) -> -1 | K19: Nov | L19: =AGPN!D17+AGPc!D17+AGPs!D16 -> 22982352166 | M19: =AGPN!E17+AGPc!E17+AGPs!E16 -> 21338105910 | N19: =AGPN!F17+AGPc!F17+AGPs!F16 -> 33760000000 | O19: =AGPc!G17 -> 0 | P19: =AGPs!G16 -> 0 | Q19: =AGPN!G17 -> 0 | R19: =AGPN!G17+AGPc!G17+AGPs!G16 -> 0 | S19: =IFERROR(R19/N19,0) -> 0 | T19: =IFERROR(R19/L19-1,0) -> -1 | U19: =IFERROR(R19/M19-1,0) -> -1
B20: Sem 2 | C20: =SUM(C14:C19) -> 153843013853 | D20: =SUM(D14:D19) -> 154544412708 | E20: =SUM(E14:E19) -> 229800000000 | F20: =SUM(F14:F19) -> 6.9203163e+10 | G20: =IFERROR(F20/E20,0) -> 0.30114518 | H20: =IFERROR(F20/C20-1,0) -> -0.55017026 | I20: =IFERROR(F20/D20-1,0) -> -0.55221181 | K20: Dec | L20: =AGPN!D18+AGPc!D18+AGPs!D17 -> 23453987016 | M20: =AGPN!E18+AGPc!E18+AGPs!E17 -> 24093261177 | N20: =AGPN!F18+AGPc!F18+AGPs!F17 -> 33760000000 | O20: =AGPc!G18 -> 0 | P20: =AGPs!G17 -> 0 | Q20: =AGPN!G18 -> 0 | R20: =AGPN!G18+AGPc!G18+AGPs!G17 -> 0 | S20: =IFERROR(R20/N20,0) -> 0 | T20: =IFERROR(R20/L20-1,0) -> -1 | U20: =IFERROR(R20/M20-1,0) -> -1
B21: TOTAL YTD | C21: =C13+C20 -> 295250474464 | D21: =D13+D20 -> 296500004428 | E21: =E13+E20 -> 461220000000 | F21: =F13+F20 -> 2.0557422e+11 | G21: =IFERROR(F21/E21,0) -> 0.44571835 | H21: =IFERROR(F21/C21-1,0) -> -0.30372943 | I21: =IFERROR(F21/D21-1,0) -> -0.3066637 | K21: Sem 2 | L21: =SUM(L15:L20) -> 142431678034 | M21: =SUM(M15:M20) -> 140298524452 | N21: =SUM(N15:N20) -> 208800000000 | O21: =SUM(O15:O20) -> 2.9676664e+10 | P21: =SUM(P15:P20) -> 2.2989674e+10 | Q21: =SUM(Q15:Q20) -> 1.1666416e+10 | R21: =SUM(R15:R20) -> 6.4332753e+10 | S21: =IFERROR(R21/N21,0) -> 0.30810706 | T21: =IFERROR(R21/L21-1,0) -> -0.54832553 | U21: =IFERROR(R21/M21-1,0) -> -0.54145809
B22: AVG YTD | C22: =IFERROR(AVERAGE(C7:C12,C14:C19),0) -> 2.4604206e+10 | D22: =IFERROR(AVERAGE(D7:D12,D14:D19),0) -> 2.4708334e+10 | E22: =IFERROR(AVERAGE(E7:E12,E14:E19),0) -> 38435000000 | F22: =IFERROR(AVERAGE(F7:F12,F14:F19),0) -> 1.7131185e+10 | G22: =IFERROR(F22/E22,0) -> 0.44571835 | H22: =IFERROR(F22/C22-1,0) -> -0.30372943 | I22: =IFERROR(F22/D22-1,0) -> -0.3066637 | K22: TOTAL YTD | L22: =L14+L21 -> 273822407071 | M22: =M14+M21 -> 272293401861 | N22: =N14+N21 -> 417600000000 | O22: =O14+O21 -> 8.4170166e+10 | P22: =P14+P21 -> 6.7564582e+10 | Q22: =Q14+Q21 -> 3.5536555e+10 | R22: =R14+R21 -> 1.872713e+11 | S22: =IFERROR(R22/N22,0) -> 0.44844661 | T22: =IFERROR(R22/L22-1,0) -> -0.31608481 | U22: =IFERROR(R22/M22-1,0) -> -0.31224443
K23: AVG YTD | L23: =IFERROR(AVERAGE(L8:L13,L15:L20),0) -> 2.2818534e+10 | M23: =IFERROR(AVERAGE(M8:M13,M15:M20),0) -> 2.2691117e+10 | N23: =IFERROR(AVERAGE(N8:N13,N15:N20),0) -> 34800000000 | O23: =IFERROR(AVERAGE(O8:O13,O15:O20),0) -> 7.0141805e+09 | P23: =IFERROR(AVERAGE(P8:P13,P15:P20),0) -> 5.6303818e+09 | Q23: =IFERROR(AVERAGE(Q8:Q13,Q15:Q20),0) -> 2.9613796e+09 | R23: =IFERROR(AVERAGE(R8:R13,R15:R20),0) -> 1.5605942e+10 | S23: =IFERROR(R23/N23,0) -> 0.44844661 | T23: =IFERROR(R23/L23-1,0) -> -0.31608481 | U23: =IFERROR(R23/M23-1,0) -> -0.31224443
B26: TEAM PENJUALAN KANTOR
B29: Month | C29: TEAM PENJUALAN KANTOR | H29: Growth
C30: 2024 | D30: 2025 | E30: TGT 2026 | F30: 2026 | G30: ACH | H30: 26 vs 24 | I30: 26 vs 25
B31: Jan | C31: 1351861125 | D31: 761652488 | E31: 2500000000 | F31: 1.477951e+09 | G31: =IFERROR(F31/E31,0) -> 0.5911804 | H31: =IFERROR(F31/C31-1,0) -> 0.093271322 | I31: =IFERROR(F31/D31-1,0) -> 0.94045319
B32: Feb | C32: 1313326478 | D32: 1842823977 | E32: 2500000000 | F32: 1.6583126e+09 | G32: =IFERROR(F32/E32,0) -> 0.66332505 | H32: =IFERROR(F32/C32-1,0) -> 0.26268118 | I32: =IFERROR(F32/D32-1,0) -> -0.10012424
B33: Mar | C33: 1843100790 | D33: 1501617641 | E33: 2500000000 | F33: 9.0118811e+08 | G33: =IFERROR(F33/E33,0) -> 0.36047525 | H33: =IFERROR(F33/C33-1,0) -> -0.51104784 | I33: =IFERROR(F33/D33-1,0) -> -0.39985514
B34: Apr | C34: 810730679 | D34: 1057406211 | E34: 2500000000 | F34: 1.4225553e+09 | G34: =IFERROR(F34/E34,0) -> 0.56902211 | H34: =IFERROR(F34/C34-1,0) -> 0.75465825 | I34: =IFERROR(F34/D34-1,0) -> 0.34532525
B35: May | C35: 1514360126 | D35: 1745544024 | E35: 2500000000 | F35: 1.4803984e+09 | G35: =IFERROR(F35/E35,0) -> 0.59215936 | H35: =IFERROR(F35/C35-1,0) -> -0.022426449 | I35: =IFERROR(F35/D35-1,0) -> -0.15189856
B36: Jun | C36: 1861002962 | D36: 1281644123 | E36: 2500000000 | F36: 1.701492e+09 | G36: =IFERROR(F36/E36,0) -> 0.68059681 | H36: =IFERROR(F36/C36-1,0) -> -0.085712344 | I36: =IFERROR(F36/D36-1,0) -> 0.32758541
B37: Sem1 | C37: =SUM(C31:C36) -> 8694382160 | D37: =SUM(D31:D36) -> 8190688464 | E37: =SUM(E31:E36) -> 15000000000 | F37: =SUM(F31:F36) -> 8.6418975e+09 | G37: =IFERROR(F37/E37,0) -> 0.5761265 | H37: =IFERROR(F37/C37-1,0) -> -0.0060366226 | I37: =IFERROR(F37/D37-1,0) -> 0.055088042
B38: Jul | C38: 1666498542 | D38: 1358009119 | E38: 2500000000 | F38: 1.7738397e+09 | G38: =IFERROR(F38/E38,0) -> 0.70953589 | H38: =IFERROR(F38/C38-1,0) -> 0.0644112 | I38: =IFERROR(F38/D38-1,0) -> 0.30620604
B39: Aug | C39: 1717173680 | D39: 1683837778 | E39: 2500000000 | F39: 8.2925715e+08 | G39: =IFERROR(F39/E39,0) -> 0.33170286 | H39: =IFERROR(F39/C39-1,0) -> -0.51708021 | I39: =IFERROR(F39/D39-1,0) -> -0.50751957
B40: Sep | C40: 1702529602 | D40: 1577780609 | E40: 2500000000 | F40: 0 | G40: =IFERROR(F40/E40,0) -> 0 | H40: =IFERROR(F40/C40-1,0) -> -1 | I40: =IFERROR(F40/D40-1,0) -> -1
B41: Oct | C41: 1095384981 | D41: 2019064235 | E41: 2500000000 | F41: 0 | G41: =IFERROR(F41/E41,0) -> 0 | H41: =IFERROR(F41/C41-1,0) -> -1 | I41: =IFERROR(F41/D41-1,0) -> -1
B42: Nov | C42: 1354726476 | D42: 2118384627 | E42: 2500000000 | F42: 0 | G42: =IFERROR(F42/E42,0) -> 0 | H42: =IFERROR(F42/C42-1,0) -> -1 | I42: =IFERROR(F42/D42-1,0) -> -1
B43: Dec | C43: 1789557012 | D43: 2362184036 | E43: 2500000000 | F43: 0 | G43: =IFERROR(F43/E43,0) -> 0 | H43: =IFERROR(F43/C43-1,0) -> -1 | I43: =IFERROR(F43/D43-1,0) -> -1
B44: Sem 2 | C44: =SUM(C38:C43) -> 9325870293 | D44: =SUM(D38:D43) -> 11119260404 | E44: =SUM(E38:E43) -> 15000000000 | F44: =SUM(F38:F43) -> 2.6030969e+09 | G44: =IFERROR(F44/E44,0) -> 0.17353979 | H44: =IFERROR(F44/C44-1,0) -> -0.72087357 | I44: =IFERROR(F44/D44-1,0) -> -0.76589299
B45: TOTAL YTD | C45: =C37+C44 -> 18020252453 | D45: =D37+D44 -> 19309948868 | E45: =E37+E44 -> 30000000000 | F45: =F37+F44 -> 1.1244994e+10 | G45: =IFERROR(F45/E45,0) -> 0.37483314 | H45: =IFERROR(F45/C45-1,0) -> -0.3759802 | I45: =IFERROR(F45/D45-1,0) -> -0.417658
B46: AVG YTD | C46: =IFERROR(AVERAGE(C31:C36,C38:C43),0) -> 1.5016877e+09 | D46: =IFERROR(AVERAGE(D31:D36,D38:D43),0) -> 1.6091624e+09 | E46: =IFERROR(AVERAGE(E31:E36,E38:E43),0) -> 2500000000 | F46: =IFERROR(AVERAGE(F31:F36,F38:F43),0) -> 9.3708286e+08 | G46: =IFERROR(F46/E46,0) -> 0.37483314 | H46: =IFERROR(F46/C46-1,0) -> -0.3759802 | I46: =IFERROR(F46/D46-1,0) -> -0.417658
B48: TEAM PENJUALAN GREEN GO
...

Sheet TELE
C3: TELEMARKETING
C6: Month | D6: PENJUALAN TELEMARKETING
D7: 2025 | E7: TGT 2026 | F7: 2026 | G7: ACH
C8: Jan | D8: 0 | E8: 1040000000 | F8: 152332443 | G8: =IFERROR(F8/E8,0) -> 0.1464735
C9: Feb | D9: 0 | E9: 1040000000 | F9: 2.113022e+08 | G9: =IFERROR(F9/E9,0) -> 0.20317519
C10: Mar | D10: 0 | E10: 1040000000 | F10: 2.1298792e+08 | G10: =IFERROR(F10/E10,0) -> 0.20479607
C11: Apr | D11: 0 | E11: 500000000 | F11: 5.6149107e+08 | G11: =IFERROR(F11/E11,0) -> 1.1229821
C12: May | D12: 6953873 | E12: 500000000 | F12: 5.1190568e+08 | G12: =IFERROR(F12/E12,0) -> 1.0238114
C13: Jun | D13: 44252286 | E13: 500000000 | F13: ='TELE-Harian'!E14 -> 5.9861653e+08 | G13: =IFERROR(F13/E13,0) -> 1.1972331
C14: Sem1 | D14: =SUM(D8:D13) -> 51206159 | E14: =SUM(E8:E13) -> 4620000000 | F14: =SUM(F8:F13) -> 2.2486358e+09 | G14: =IFERROR(F14/E14,0) -> 0.48671771
C15: Jul | D15: 51748216 | E15: 500000000 | F15: ='TELE-Harian'!E26 -> 5.7220066e+08 | G15: =IFERROR(F15/E15,0) -> 1.1444013
C16: Aug | D16: 49134832 | E16: 500000000 | F16: ='TELE-Harian'!E37 -> 6.5999936e+08 | G16: =IFERROR(F16/E16,0) -> 1.3199987
C17: Sep | D17: 89081629 | E17: 500000000 | F17: ='TELE-Harian'!E48 -> 5.6485372e+08 | G17: =IFERROR(F17/E17,0) -> 1.1297074
C18: Oct | D18: 136198040 | E18: 500000000 | F18: 0 | G18: =IFERROR(F18/E18,0) -> 0
C19: Nov | D19: 169964820 | E19: 500000000 | F19: 0 | G19: =IFERROR(F19/E19,0) -> 0
C20: Dec | D20: 122309696 | E20: 500000000 | F20: 0 | G20: =IFERROR(F20/E20,0) -> 0
C21: Sem 2 | D21: =SUM(D15:D20) -> 618437233 | E21: =SUM(E15:E20) -> 3000000000 | F21: =SUM(F15:F20) -> 1.7970537e+09 | G21: =IFERROR(F21/E21,0) -> 0.59901791
C22: TOTAL YTD | D22: =D14+D21 -> 669643392 | E22: =E14+E21 -> 7620000000 | F22: =F14+F21 -> 4.0456896e+09 | G22: =IFERROR(F22/E22,0) -> 0.53093039
C23: AVG YTD | D23: =IFERROR(AVERAGE(D12:D13,D15:D20),0) -> 83705424 | E23: =IFERROR(AVERAGE(E8:E13,E15:E20),0) -> 635000000 | F23: =IFERROR(AVERAGE(F8:F13,F15:F20),0) -> 3.371408e+08 | G23: =IFERROR(F23/E23,0) -> 0.53093039

Sheet AGPN
C4: Month | D4: TEAM PENJUALAN AGPN | I4: Growth
D5: 2024 | E5: 2025 | F5: TGT 2026 | G5: 2026 | H5: ACH | I5: 26 vs 24 | J5: 26 vs 25
C6: Jan | D6: =D40+M40+D63 -> 5619094995 | E6: =E40+N40+E63 -> 3574991702 | F6: =F40+O40+F63 -> 8800000000 | G6: =G40+P40+G63 -> 5016540388 | H6: =IFERROR(G6/F6,0) -> 0.57006141 | I6: =IFERROR(G6/D6-1,0) -> -0.10723339 | J6: =IFERROR(G6/E6-1,0) -> 0.40323134
C7: Feb | D7: =D41+M41+D64 -> 5052316572 | E7: =E41+N41+E64 -> 4606804951 | F7: =F41+O41+F64 -> 8800000000 | G7: =G41+P41+G64 -> 5.0309831e+09 | H7: =IFERROR(G7/F7,0) -> 0.57170262 | I7: =IFERROR(G7/D7-1,0) -> -0.0042225159 | J7: =IFERROR(G7/E7-1,0) -> 0.092076426
C8: Mar | D8: =D42+M42+D65 -> 3913099239 | E8: =E42+N42+E65 -> 3779221983 | F8: =F42+O42+F65 -> 8800000000 | G8: =G42+P42+G65 -> 2.3041601e+09 | H8: =IFERROR(G8/F8,0) -> 0.26183638 | I8: =IFERROR(G8/D8-1,0) -> -0.41116747 | J8: =IFERROR(G8/E8-1,0) -> -0.39030834
C9: Apr | D9: =D43+M43+D66 -> 2767402303 | E9: =E43+N43+E66 -> 4097804836 | F9: =F43+O43+F66 -> 8800000000 | G9: =G43+P43+G66 -> 4.8171723e+09 | H9: =IFERROR(G9/F9,0) -> 0.54740594 | I9: =IFERROR(G9/D9-1,0) -> 0.74068377 | J9: =IFERROR(G9/E9-1,0) -> 0.17554946
C10: May | D10: =D44+M44+D67 -> 4955893592 | E10: =E44+N44+E67 -> 4574934934 | F10: =F44+O44+F67 -> 8800000000 | G10: =G44+P44+G67 -> 3.2575439e+09 | H10: =IFERROR(G10/F10,0) -> 0.37017545 | I10: =IFERROR(G10/D10-1,0) -> -0.34269292 | J10: =IFERROR(G10/E10-1,0) -> -0.28795841
C11: Jun | D11: =D45+M45+D68 -> 5312328160 | E11: =E45+N45+E68 -> 3888923990 | F11: =F45+O45+F68 -> 8800000000 | G11: =G45+P45+G68 -> 3.4437395e+09 | H11: =IFERROR(G11/F11,0) -> 0.39133404 | I11: =IFERROR(G11/D11-1,0) -> -0.35174571 | J11: =IFERROR(G11/E11-1,0) -> -0.11447497
C12: Sem1 | D12: =SUM(D6:D11) -> 27620134861 | E12: =SUM(E6:E11) -> 24522682396 | F12: =SUM(F6:F11) -> 52800000000 | G12: =SUM(G6:G11) -> 2.3870139e+10 | H12: =IFERROR(G12/F12,0) -> 0.45208597 | I12: =IFERROR(G12/D12-1,0) -> -0.13577036 | J12: =IFERROR(G12/E12-1,0) -> -0.026609775
C13: Jul | D13: =D47+M47+D70 -> 4524480100 | E13: =E47+N47+E70 -> 4239851823 | F13: =F47+O47+F70 -> 8800000000 | G13: =G47+P47+G70 -> 4.926376e+09 | H13: =IFERROR(G13/F13,0) -> 0.55981546 | I13: =IFERROR(G13/D13-1,0) -> 0.088826982 | J13: =IFERROR(G13/E13-1,0) -> 0.16192174
C14: Aug | D14: =D48+M48+D71 -> 4828238763 | E14: =E48+N48+E71 -> 4537641777 | F14: =F48+O48+F71 -> 8800000000 | G14: =G48+P48+G71 -> 3.659961e+09 | H14: =IFERROR(G14/F14,0) -> 0.41590465 | I14: =IFERROR(G14/D14-1,0) -> -0.2419677 | J14: =IFERROR(G14/E14-1,0) -> -0.19342224
C15: Sep | D15: =D49+M49+D72 -> 4023405984 | E15: =E49+N49+E72 -> 4686321831 | F15: =F49+O49+F72 -> 8800000000 | G15: =G49+P49+G72 -> 3.0800791e+09 | H15: =IFERROR(G15/F15,0) -> 0.35000899 | I15: =IFERROR(G15/D15-1,0) -> -0.23445978 | J15: =IFERROR(G15/E15-1,0) -> -0.34275127
C16: Oct | D16: =D50+M50+D73 -> 4796604815 | E16: =E50+N50+E73 -> 4743458863 | F16: =F50+O50+F73 -> 8800000000 | G16: =G50+P50+G73 -> 0 | H16: =IFERROR(G16/F16,0) -> 0 | I16: =IFERROR(G16/D16-1,0) -> -1 | J16: =IFERROR(G16/E16-1,0) -> -1
C17: Nov | D17: =D51+M51+D74 -> 4021067246 | E17: =E51+N51+E74 -> 4317909388 | F17: =F51+O51+F74 -> 8800000000 | G17: =G51+P51+G74 -> 0 | H17: =IFERROR(G17/F17,0) -> 0 | I17: =IFERROR(G17/D17-1,0) -> -1 | J17: =IFERROR(G17/E17-1,0) -> -1
C18: Dec | D18: =D52+M52+D75 -> 4430267783 | E18: =E52+N52+E75 -> 5001863423 | F18: =F52+O52+F75 -> 8800000000 | G18: =G52+P52+G75 -> 0 | H18: =IFERROR(G18/F18,0) -> 0 | I18: =IFERROR(G18/D18-1,0) -> -1 | J18: =IFERROR(G18/E18-1,0) -> -1
C19: Sem 2 | D19: =SUM(D13:D18) -> 26624064691 | E19: =SUM(E13:E18) -> 27527047105 | F19: =SUM(F13:F18) -> 52800000000 | G19: =SUM(G13:G18) -> 1.1666416e+10 | H19: =IFERROR(G19/F19,0) -> 0.22095485 | I19: =IFERROR(G19/D19-1,0) -> -0.56180936 | J19: =IFERROR(G19/E19-1,0) -> -0.57618353
C20: TOTAL YTD | D20: =D12+D19 -> 54244199552 | E20: =E12+E19 -> 52049729501 | F20: =F12+F19 -> 105600000000 | G20: =G12+G19 -> 3.5536555e+10 | H20: =IFERROR(G20/F20,0) -> 0.33652041 | I20: =IFERROR(G20/D20-1,0) -> -0.34487824 | J20: =IFERROR(G20/E20-1,0) -> -0.31725764
C21: AVG YTD | D21: =IFERROR(AVERAGE(D6:D11,D13:D18),0) -> 4.52035e+09 | E21: =IFERROR(AVERAGE(E6:E11,E13:E18),0) -> 4.3374775e+09 | F21: =IFERROR(AVERAGE(F6:F11,F13:F18),0) -> 8800000000 | G21: =IFERROR(AVERAGE(G6:G11,G13:G18),0) -> 2.9613796e+09 | H21: =IFERROR(G21/F21,0) -> 0.33652041 | I21: =IFERROR(G21/D21-1,0) -> -0.34487824 | J21: =IFERROR(G21/E21-1,0) -> -0.31725764
C23: 2024 -2025 | G23: ACH 2026 vs TGT 2026
C25: =E20-D20 -> -2194470051
G26: =G20-F20 -> -7.0063445e+10
C27: 2025 -2026
C29: =G20-E20 -> -1.6513174e+10 | G29: TANDA TANGAN SCM
C35: TEAM PENJUALAN AGPN - LUAR PULAU | L35: TEAM PENJUALAN CIKAMPEK
C38: Month | D38: TEAM PENJUALAN LUAR PULAU | I38: Growth | L38: Month | M38: TEAM PENJUALAN AGPN - CIKAMPEK | R38: Growth
D39: 2024 | E39: 2025 | F39: TGT 2026 | G39: 2026 | H39: ACH | I39: 26 vs 24 | J39: 26 vs 25 | M39: 2024 | N39: 2025 | O39: TGT 2026 | P39: 2026 | Q39: ACH | R39: 26 vs 24 | S39: 26 vs 25
C40: Jan | D40: 2951632629 | E40: 1246298071 | F40: 5500000000 | G40: ='AGPn-Harian'!E19 -> 2541489240 | H40: =IFERROR(G40/F40,0) -> 0.46208895 | I40: =IFERROR(G40/D40-1,0) -> -0.13895476 | J40: =IFERROR(G40/E40-1,0) -> 1.0392307 | L40: Jan | M40: 2144848271 | N40: 1793833641 | O40: 2000000000 | P40: ='AGPn-Harian'!E24 -> 1547094181 | Q40: =IFERROR(P40/O40,0) -> 0.77354709 | R40: =IFERROR(P40/M40-1,0) -> -0.27869295 | S40: =IFERROR(P40/N40-1,0) -> -0.13754869
C41: Feb | D41: 2595950273 | E41: 2756777946 | F41: 5500000000 | G41: ='AGPn-Harian'!E56 -> 2.2092057e+09 | H41: =IFERROR(G41/F41,0) -> 0.40167376 | I41: =IFERROR(G41/D41-1,0) -> -0.14897996 | J41: =IFERROR(G41/E41-1,0) -> -0.19862762 | L41: Feb | M41: 1974281424 | N41: 1304399527 | O41: 2000000000 | P41: ='AGPn-Harian'!E63 -> 1.7461355e+09 | Q41: =IFERROR(P41/O41,0) -> 0.87306777 | R41: =IFERROR(P41/M41-1,0) -> -0.11555895 | S41: =IFERROR(P41/N41-1,0) -> 0.33865085
C42: Mar | D42: 1839478427 | E42: 1714603742 | F42: 5500000000 | G42: ='AGPn-Harian'!E93 -> 6.5358174e+08 | H42: =IFERROR(G42/F42,0) -> 0.11883304 | I42: =IFERROR(G42/D42-1,0) -> -0.64469182 | J42: =IFERROR(G42/E42-1,0) -> -0.6188147 | L42: Mar | M42: 1543723791 | N42: 1573577016 | O42: 2000000000 | P42: ='AGPn-Harian'!E100 -> 1.0694967e+09 | Q42: =IFERROR(P42/O42,0) -> 0.53474837 | R42: =IFERROR(P42/M42-1,0) -> -0.30719682 | S42: =IFERROR(P42/N42-1,0) -> -0.32034038
C43: Apr | D43: 1249970715 | E43: 2142254698 | F43: 5500000000 | G43: ='AGPn-Harian'!E130 -> 1.7240114e+09 | H43: =IFERROR(G43/F43,0) -> 0.31345661 | I43: =IFERROR(G43/D43-1,0) -> 0.3792414 | J43: =IFERROR(G43/E43-1,0) -> -0.19523511 | L43: Apr | M43: 1240020864 | N43: 1532695868 | O43: 2000000000 | P43: ='AGPn-Harian'!E137 -> 2.4098546e+09 | Q43: =IFERROR(P43/O43,0) -> 1.2049273 | R43: =IFERROR(P43/M43-1,0) -> 0.94339839 | S43: =IFERROR(P43/N43-1,0) -> 0.57229794
C44: May | D44: 2290408512 | E44: 2293877298 | F44: 5500000000 | G44: ='AGPn-Harian'!E167 -> 1.5029642e+09 | H44: =IFERROR(G44/F44,0) -> 0.27326623 | I44: =IFERROR(G44/D44-1,0) -> -0.34380079 | J44: =IFERROR(G44/E44-1,0) -> -0.34479309 | L44: May | M44: 2133924535 | N44: 1507889574 | O44: 2000000000 | P44: ='AGPn-Harian'!E174 -> 1.1816064e+09 | Q44: =IFERROR(P44/O44,0) -> 0.59080319 | R44: =IFERROR(P44/M44-1,0) -> -0.44627546 | S44: =IFERROR(P44/N44-1,0) -> -0.216384
C45: Jun | D45: 2659615300 | E45: 1839629453 | F45: 5500000000 | G45: ='AGPn-Harian'!E204 -> 1.3219244e+09 | H45: =IFERROR(G45/F45,0) -> 0.24034989 | I45: =IFERROR(G45/D45-1,0) -> -0.50296407 | J45: =IFERROR(G45/E45-1,0) -> -0.28141813 | L45: Jun | M45: 2102051274 | N45: 1483982175 | O45: 2000000000 | P45: ='AGPn-Harian'!E211 -> 1.4182772e+09 | Q45: =IFERROR(P45/O45,0) -> 0.70913858 | R45: =IFERROR(P45/M45-1,0) -> -0.32528898 | S45: =IFERROR(P45/N45-1,0) -> -0.044276144
C46: Sem1 | D46: =SUM(D40:D45) -> 13587055856 | E46: =SUM(E40:E45) -> 11993441208 | F46: =SUM(F40:F45) -> 33000000000 | G46: =SUM(G40:G45) -> 9.9531767e+09 | H46: =IFERROR(G46/F46,0) -> 0.30161141 | I46: =IFERROR(G46/D46-1,0) -> -0.26745155 | J46: =IFERROR(G46/E46-1,0) -> -0.17011502 | L46: Sem1 | M46: =SUM(M40:M45) -> 11138850159 | N46: =SUM(N40:N45) -> 9196377801 | O46: =SUM(O40:O45) -> 12000000000 | P46: =SUM(P40:P45) -> 9.3724646e+09 | Q46: =IFERROR(P46/O46,0) -> 0.78103871 | R46: =IFERROR(P46/M46-1,0) -> -0.15857881 | S46: =IFERROR(P46/N46-1,0) -> 0.019147406
C47: Jul | D47: 2366153309 | E47: 1806751811 | F47: 5500000000 | G47: ='AGPn-Harian'!E241 -> 2.2728103e+09 | H47: =IFERROR(G47/F47,0) -> 0.41323824 | I47: =IFERROR(G47/D47-1,0) -> -0.039449251 | J47: =IFERROR(G47/E47-1,0) -> 0.25795381 | L47: Jul | M47: 1733452286 | N47: 1780231920 | O47: 2000000000 | P47: ='AGPn-Harian'!E246 -> 2.0205788e+09 | Q47: =IFERROR(P47/O47,0) -> 1.0102894 | R47: =IFERROR(P47/M47-1,0) -> 0.16563856 | S47: =IFERROR(P47/N47-1,0) -> 0.13500877
C48: Aug | D48: 2510671440 | E48: 2410527884 | F48: 5500000000 | G48: ='AGPn-Harian'!E278 -> 1.7360501e+09 | H48: =IFERROR(G48/F48,0) -> 0.31564548 | I48: =IFERROR(G48/D48-1,0) -> -0.30853153 | J48: =IFERROR(G48/E48-1,0) -> -0.279805 | L48: Aug | M48: 1703564347 | N48: 1205157269 | O48: 2000000000 | P48: ='AGPn-Harian'!E283 -> 1.2411529e+09 | Q48: =IFERROR(P48/O48,0) -> 0.62057644 | R48: =IFERROR(P48/M48-1,0) -> -0.27143763 | S48: =IFERROR(P48/N48-1,0) -> 0.029867982
C49: Sep | D49: 2000568212 | E49: 2355545193 | F49: 5500000000 | G49: ='AGPn-Harian'!E315 -> 1.269396e+09 | H49: =IFERROR(G49/F49,0) -> 0.23079927 | I49: =IFERROR(G49/D49-1,0) -> -0.36548228 | J49: =IFERROR(G49/E49-1,0) -> -0.46110311 | L49: Sep | M49: 1507269278 | N49: 1605142366 | O49: 2000000000 | P49: ='AGPn-Harian'!E322 -> 1.4500042e+09 | Q49: =IFERROR(P49/O49,0) -> 0.72500209 | R49: =IFERROR(P49/M49-1,0) -> -0.037992611 | S49: =IFERROR(P49/N49-1,0) -> -0.096650731
C50: Oct | D50: 2567361124 | E50: 1988159250 | F50: 5500000000 | G50: 0 | H50: =IFERROR(G50/F50,0) -> 0 | I50: =IFERROR(G50/D50-1,0) -> -1 | J50: =IFERROR(G50/E50-1,0) -> -1 | L50: Oct | M50: 1645482434 | N50: 1792454231 | O50: 2000000000 | P50: 0 | Q50: =IFERROR(P50/O50,0) -> 0 | R50: =IFERROR(P50/M50-1,0) -> -1 | S50: =IFERROR(P50/N50-1,0) -> -1
C51: Nov | D51: 1746323926 | E51: 2083667566 | F51: 5500000000 | G51: 0 | H51: =IFERROR(G51/F51,0) -> 0 | I51: =IFERROR(G51/D51-1,0) -> -1 | J51: =IFERROR(G51/E51-1,0) -> -1 | L51: Nov | M51: 1613146475 | N51: 1393255787 | O51: 2000000000 | P51: 0 | Q51: =IFERROR(P51/O51,0) -> 0 | R51: =IFERROR(P51/M51-1,0) -> -1 | S51: =IFERROR(P51/N51-1,0) -> -1
C52: Dec | D52: 2370917248 | E52: 2531555300 | F52: 5500000000 | G52: 0 | H52: =IFERROR(G52/F52,0) -> 0 | I52: =IFERROR(G52/D52-1,0) -> -1 | J52: =IFERROR(G52/E52-1,0) -> -1 | L52: Dec | M52: 1437922484 | N52: 1745787005 | O52: 2000000000 | P52: 0 | Q52: =IFERROR(P52/O52,0) -> 0 | R52: =IFERROR(P52/M52-1,0) -> -1 | S52: =IFERROR(P52/N52-1,0) -> -1
C53: Sem 2 | D53: =SUM(D47:D52) -> 13561995259 | E53: =SUM(E47:E52) -> 13176207004 | F53: =SUM(F47:F52) -> 33000000000 | G53: =SUM(G47:G52) -> 5.2782564e+09 | H53: =IFERROR(G53/F53,0) -> 0.15994717 | I53: =IFERROR(G53/D53-1,0) -> -0.61080532 | J53: =IFERROR(G53/E53-1,0) -> -0.59941002 | L53: Sem 2 | M53: =SUM(M47:M52) -> 9640837304 | N53: =SUM(N47:N52) -> 9522028578 | O53: =SUM(O47:O52) -> 12000000000 | P53: =SUM(P47:P52) -> 4.7117359e+09 | Q53: =IFERROR(P53/O53,0) -> 0.39264466 | R53: =IFERROR(P53/M53-1,0) -> -0.51127317 | S53: =IFERROR(P53/N53-1,0) -> -0.5051752
...

Sheet AGPc
C4: Month | D4: TEAM PENJUALAN AGPc | I4: Growth
D5: 2024 | E5: 2025 | F5: TGT 2026 | G5: 2026 | H5: ACH | I5: 26 vs 24 | J5: 26 vs 25
C6: Jan | D6: =SUM(D38,X38) -> 8058672985 | E6: =SUM(E38,Y38) -> 8157756904 | F6: =SUM(F38,Z38) -> 14040000000 | G6: =SUM(G38,AA38) -> 9.944665e+09 | H6: =IFERROR(G6/F6,0) -> 0.70830948 | I6: =IFERROR(G6/D6-1,0) -> 0.23403258 | J6: =IFERROR(G6/E6-1,0) -> 0.21904405
C7: Feb | D7: =SUM(D39,X39) -> 8229737374 | E7: =SUM(E39,Y39) -> 10120775617 | F7: =SUM(F39,Z39) -> 12480000000 | G7: =SUM(G39,AA39) -> 1.0890748e+10 | H7: =IFERROR(G7/F7,0) -> 0.87265607 | I7: =IFERROR(G7/D7-1,0) -> 0.32334086 | J7: =IFERROR(G7/E7-1,0) -> 0.076078374
C8: Mar | D8: =SUM(D40,X40) -> 9125985439 | E8: =SUM(E40,Y40) -> 8104379074 | F8: =SUM(F40,Z40) -> 12480000000 | G8: =SUM(G40,AA40) -> 5.2715889e+09 | H8: =IFERROR(G8/F8,0) -> 0.42240296 | I8: =IFERROR(G8/D8-1,0) -> -0.42235401 | J8: =IFERROR(G8/E8-1,0) -> -0.34953821
C9: Apr | D9: =SUM(D41,X41) -> 4936471484 | E9: =SUM(E41,Y41) -> 7076193389 | F9: =SUM(F41,Z41) -> 14040000000 | G9: =SUM(G41,AA41) -> 9.1031812e+09 | H9: =IFERROR(G9/F9,0) -> 0.64837473 | I9: =IFERROR(G9/D9-1,0) -> 0.8440664 | J9: =IFERROR(G9/E9-1,0) -> 0.28645173
C10: May | D10: =SUM(D42,X42) -> 8585568703 | E10: =SUM(E42,Y42) -> 10219021338 | F10: =SUM(F42,Z42) -> 12480000000 | G10: =SUM(G42,AA42) -> 9.594543e+09 | H10: =IFERROR(G10/F10,0) -> 0.76879351 | I10: =IFERROR(G10/D10-1,0) -> 0.1175198 | J10: =IFERROR(G10/E10-1,0) -> -0.061109408
C11: Jun | D11: =SUM(D43,X43) -> 10434470118 | E11: =SUM(E43,Y43) -> 9621574876 | F11: =SUM(F43,Z43) -> 12480000000 | G11: =SUM(G43,AA43) -> 9.6887769e+09 | H11: =IFERROR(G11/F11,0) -> 0.7763443 | I11: =IFERROR(G11/D11-1,0) -> -0.071464408 | J11: =IFERROR(G11/E11-1,0) -> 0.0069845124
C12: Sem1 | D12: =SUM(D6:D11) -> 49370906103 | E12: =SUM(E6:E11) -> 53299701198 | F12: =SUM(F6:F11) -> 78000000000 | G12: =SUM(G6:G11) -> 5.4493503e+10 | H12: =IFERROR(G12/F12,0) -> 0.69863465 | I12: =IFERROR(G12/D12-1,0) -> 0.1037574 | J12: =IFERROR(G12/E12-1,0) -> 0.022397905
C13: Jul | D13: =SUM(D45,X45) -> 9077128427 | E13: =SUM(E45,Y45) -> 10523559021 | F13: =SUM(F45,Z45) -> 12480000000 | G13: =SUM(G45,AA45) -> 1.1441452e+10 | H13: =IFERROR(G13/F13,0) -> 0.91678304 | I13: =IFERROR(G13/D13-1,0) -> 0.26047047 | J13: =IFERROR(G13/E13-1,0) -> 0.087222705
C14: Aug | D14: =SUM(D46,X46) -> 9624644911 | E14: =SUM(E46,Y46) -> 9712799769 | F14: =SUM(F46,Z46) -> 14040000000 | G14: =SUM(G46,AA46) -> 1.0463408e+10 | H14: =IFERROR(G14/F14,0) -> 0.74525697 | I14: =IFERROR(G14/D14-1,0) -> 0.087147416 | J14: =IFERROR(G14/E14-1,0) -> 0.0772803
C15: Sep | D15: =SUM(D47,X47) -> 9799462248 | E15: =SUM(E47,Y47) -> 10201204794 | F15: =SUM(F47,Z47) -> 12480000000 | G15: =SUM(G47,AA47) -> 7.7718034e+09 | H15: =IFERROR(G15/F15,0) -> 0.62274066 | I15: =IFERROR(G15/D15-1,0) -> -0.20691531 | J15: =IFERROR(G15/E15-1,0) -> -0.23814847
C16: Oct | D16: =SUM(D48,X48) -> 9861295397 | E16: =SUM(E48,Y48) -> 10115994802 | F16: =SUM(F48,Z48) -> 14040000000 | G16: =SUM(G48,AA48) -> 0 | H16: =IFERROR(G16/F16,0) -> 0 | I16: =IFERROR(G16/D16-1,0) -> -1 | J16: =IFERROR(G16/E16-1,0) -> -1
C17: Nov | D17: =SUM(D49,X49) -> 9498552111 | E17: =SUM(E49,Y49) -> 8931575417 | F17: =SUM(F49,Z49) -> 12480000000 | G17: =SUM(G49,AA49) -> 0 | H17: =IFERROR(G17/F17,0) -> 0 | I17: =IFERROR(G17/D17-1,0) -> -1 | J17: =IFERROR(G17/E17-1,0) -> -1
C18: Dec | D18: =SUM(D50,X50) -> 9371173337 | E18: =SUM(E50,Y50) -> 10887305064 | F18: =SUM(F50,Z50) -> 12480000000 | G18: =SUM(G50,AA50) -> 0 | H18: =IFERROR(G18/F18,0) -> 0 | I18: =IFERROR(G18/D18-1,0) -> -1 | J18: =IFERROR(G18/E18-1,0) -> -1
C19: Sem 2 | D19: =SUM(D13:D18) -> 57232256431 | E19: =SUM(E13:E18) -> 60372438867 | F19: =SUM(F13:F18) -> 78000000000 | G19: =SUM(G13:G18) -> 2.9676664e+10 | H19: =IFERROR(G19/F19,0) -> 0.38047005 | I19: =IFERROR(G19/D19-1,0) -> -0.48146962 | J19: =IFERROR(G19/E19-1,0) -> -0.50844021
C20: TOTAL YTD | D20: =D12+D19 -> 106603162534 | E20: =E12+E19 -> 113672140065 | F20: =F12+F19 -> 156000000000 | G20: =G12+G19 -> 8.4170166e+10 | H20: =IFERROR(G20/F20,0) -> 0.53955235 | I20: =IFERROR(G20/D20-1,0) -> -0.21043462 | J20: =IFERROR(G20/E20-1,0) -> -0.25953566
C21: AVG YTD | D21: =IFERROR(AVERAGE(D6:D11,D13:D18),0) -> 8.8835969e+09 | E21: =IFERROR(AVERAGE(E6:E11,E13:E18),0) -> 9.4726783e+09 | F21: =IFERROR(AVERAGE(F6:F11,F13:F18),0) -> 13000000000 | G21: =IFERROR(AVERAGE(G6:G11,G13:G18),0) -> 7.0141805e+09 | H21: =IFERROR(G21/F21,0) -> 0.53955235 | I21: =IFERROR(G21/D21-1,0) -> -0.21043462 | J21: =IFERROR(G21/E21-1,0) -> -0.25953566
C23: 2024 -2025 | G23: ACH 2026 vs TGT 2026
C25: =E20-D20 -> 7068977531
G26: =G20-F20 -> -7.1829834e+10
C27: 2025 -2026
C29: =G20-E20 -> -2.9501974e+10 | G29: TANDA TANGAN SCM
C36: Month | D36: AGPc BJB | I36: Growth | L36: Month | M36: BANTEN - BEKASI | P36: CHRISTOPER | R36: Growth | W36: Month | X36: AGPc JJB | AC36: Growth | AF36: Month | AG36: JAKARTA BAT - PUS | AJ36: AHMAD | AL36: Growth
D37: 2024 | E37: 2025 | F37: TGT 2026 | G37: 2026 | H37: ACH | I37: 26 vs 24 | J37: 26 vs 25 | M37: 2024 | N37: 2025 | O37: TGT 2026 | P37: 2026 | Q37: ACH | R37: 26 vs 24 | S37: 26 vs 25 | X37: 2024 | Y37: 2025 | Z37: TGT 2026 | AA37: 2026 | AB37: ACH | AC37: 26 vs 24 | AD37: 26 vs 25 | AG37: 2024 | AH37: 2025 | AI37: TGT 2026 | AJ37: 2026 | AK37: ACH | AL37: 26 vs 24 | AM37: 26 vs 25
C38: Jan | D38: =SUM(M38,D57,M57,D76,M76) -> 5062166936 | E38: =SUM(N38,E57,N57,E76,N76) -> 5191078914 | F38: =SUM(O38,O57,F57,F76,O76) -> 8564400000 | G38: =SUM(P38,P57,G57,G76,P76) -> 6.8430885e+09 | H38: =IFERROR(G38/F38,0) -> 0.79901552 | I38: =IFERROR(G38/D38-1,0) -> 0.35181013 | J38: =IFERROR(G38/E38-1,0) -> 0.31824013 | L38: Jan | M38: 856129784 | N38: 1077369788 | O38: 1541592000 | P38: =JAN!N120 -> 1.0861823e+09 | Q38: =IFERROR(P38/O38,0) -> 0.70458478 | R38: =IFERROR(P38/M38-1,0) -> 0.26871216 | S38: =IFERROR(P38/N38-1,0) -> 0.0081796223 | W38: Jan | X38: =SUM(AG38,AG57,X57,X76,AG76) -> 2996506049 | Y38: =SUM(AH38,AH57,Y57,Y76,AH76) -> 2966677990 | Z38: =SUM(AI38,AI57,Z57,Z76,AI76) -> 5475600000 | AA38: =AJ38+AJ57+AJ76+AA76+AA57 -> 3.1015765e+09 | AB38: =IFERROR(AA38/Z38,0) -> 0.56643592 | AC38: =IFERROR(AA38/X38-1,0) -> 0.035064321 | AD38: =IFERROR(AA38/Y38-1,0) -> 0.045471234 | AF38: Jan | AG38: 561406635 | AH38: 522560340 | AI38: 1040364000 | AJ38: =JAN!N132 -> 5.1465533e+08 | AK38: =IFERROR(AJ38/AI38,0) -> 0.49468776 | AL38: =IFERROR(AJ38/AG38-1,0) -> -0.08327529 | AM38: =IFERROR(AJ38/AH38-1,0) -> -0.01512745
C39: Feb | D39: =SUM(M39,D58,M58,D77,M77) -> 5265595926 | E39: =SUM(N39,E58,N58,E77,N77) -> 6849410192 | F39: =SUM(O39,O58,F58,F77,O77) -> 7612800000 | G39: =SUM(P39,P58,G58,G77,P77) -> 7.1568029e+09 | H39: =IFERROR(G39/F39,0) -> 0.94010127 | I39: =IFERROR(G39/D39-1,0) -> 0.35916296 | J39: =IFERROR(G39/E39-1,0) -> 0.044878719 | L39: Feb | M39: 1053669827 | N39: 1293671358 | O39: 1370304000 | P39: =FEB!N120 -> 1.3054953e+09 | Q39: =IFERROR(P39/O39,0) -> 0.95270489 | R39: =IFERROR(P39/M39-1,0) -> 0.23899848 | S39: =IFERROR(P39/N39-1,0) -> 0.0091398477 | W39: Feb | X39: =SUM(AG39,AG58,X58,X77,AG77) -> 2964141448 | Y39: =SUM(AH39,AH58,Y58,Y77,AH77) -> 3271365425 | Z39: =SUM(AI39,AI58,Z58,Z77,AI77) -> 4867200000 | AA39: =AJ39+AJ58+AJ77+AA77+AA58 -> 3.7339448e+09 | AB39: =IFERROR(AA39/Z39,0) -> 0.76716486 | AC39: =IFERROR(AA39/X39-1,0) -> 0.25970534 | AD39: =IFERROR(AA39/Y39-1,0) -> 0.14140254 | AF39: Feb | AG39: 527139577 | AH39: 618948675 | AI39: 924768000 | AJ39: =FEB!N132 -> 7.6531692e+08 | AK39: =IFERROR(AJ39/AI39,0) -> 0.82757721 | AL39: =IFERROR(AJ39/AG39-1,0) -> 0.45182976 | AM39: =IFERROR(AJ39/AH39-1,0) -> 0.23647881
C40: Mar | D40: =SUM(M40,D59,M59,D78,M78) -> 5667927789 | E40: =SUM(N40,E59,N59,E78,N78) -> 4792266250 | F40: =SUM(O40,O59,F59,F78,O78) -> 7612800000 | G40: =SUM(P40,P59,G59,G78,P78) -> 3.3811715e+09 | H40: =IFERROR(G40/F40,0) -> 0.44414296 | I40: =IFERROR(G40/D40-1,0) -> -0.40345544 | J40: =IFERROR(G40/E40-1,0) -> -0.29445249 | L40: Mar | M40: 1095725356 | N40: 1181432496 | O40: 1370304000 | P40: =MAR!N120 -> 7.0752717e+08 | Q40: =IFERROR(P40/O40,0) -> 0.51632862 | R40: =IFERROR(P40/M40-1,0) -> -0.3542842 | S40: =IFERROR(P40/N40-1,0) -> -0.40112772 | W40: Mar | X40: =SUM(AG40,AG59,X59,X78,AG78) -> 3458057650 | Y40: =SUM(AH40,AH59,Y59,Y78,AH78) -> 3312112824 | Z40: =SUM(AI40,AI59,Z59,Z78,AI78) -> 4867200000 | AA40: =AJ40+AJ59+AJ78+AA78+AA59 -> 1.8904174e+09 | AB40: =IFERROR(AA40/Z40,0) -> 0.38839937 | AC40: =IFERROR(AA40/X40-1,0) -> -0.4533297 | AD40: =IFERROR(AA40/Y40-1,0) -> -0.42924123 | AF40: Mar | AG40: 854407184 | AH40: 676530002 | AI40: 924768000 | AJ40: =MAR!N132 -> 2.7738044e+08 | AK40: =IFERROR(AJ40/AI40,0) -> 0.29994598 | AL40: =IFERROR(AJ40/AG40-1,0) -> -0.67535334 | AM40: =IFERROR(AJ40/AH40-1,0) -> -0.58999536
C41: Apr | D41: =SUM(M41,D60,M60,D79,M79) -> 3036975894 | E41: =SUM(N41,E60,N60,E79,N79) -> 4726086385 | F41: =SUM(O41,O60,F60,F79,O79) -> 8564400000 | G41: =SUM(P41,P60,G60,G79,P79) -> 6.24178e+09 | H41: =IFERROR(G41/F41,0) -> 0.72880529 | I41: =IFERROR(G41/D41-1,0) -> 1.0552616 | J41: =IFERROR(G41/E41-1,0) -> 0.32070798 | L41: Apr | M41: 684069851 | N41: 713434623 | O41: 1541592000 | P41: =APR!N120 -> 9.551786e+08 | Q41: =IFERROR(P41/O41,0) -> 0.61960532 | R41: =IFERROR(P41/M41-1,0) -> 0.39631735 | S41: =IFERROR(P41/N41-1,0) -> 0.33884531 | W41: Apr | X41: =SUM(AG41,AG60,X60,X79,AG79) -> 1899495590 | Y41: =SUM(AH41,AH60,Y60,Y79,AH79) -> 2350107004 | Z41: =SUM(AI41,AI60,Z60,Z79,AI79) -> 5475600000 | AA41: =AJ41+AJ60+AJ79+AA79+AA60 -> 2.8614012e+09 | AB41: =IFERROR(AA41/Z41,0) -> 0.52257309 | AC41: =IFERROR(AA41/X41-1,0) -> 0.50640056 | AD41: =IFERROR(AA41/Y41-1,0) -> 0.2175621 | AF41: Apr | AG41: 441878805 | AH41: 411979333 | AI41: 1040364000 | AJ41: =APR!N132 -> 4.8649804e+08 | AK41: =IFERROR(AJ41/AI41,0) -> 0.46762291 | AL41: =IFERROR(AJ41/AG41-1,0) -> 0.10097619 | AM41: =IFERROR(AJ41/AH41-1,0) -> 0.18087972
C42: May | D42: =SUM(M42,D61,M61,D80,M80) -> 5755695776 | E42: =SUM(N42,E61,N61,E80,N80) -> 6884974166 | F42: =SUM(O42,O61,F61,F80,O80) -> 7612800000 | G42: =SUM(P42,P61,G61,G80,P80) -> 6.3795193e+09 | H42: =IFERROR(G42/F42,0) -> 0.83799907 | I42: =IFERROR(G42/D42-1,0) -> 0.10838369 | J42: =IFERROR(G42/E42-1,0) -> -0.073414196 | L42: May | M42: 1117192553 | N42: 1401425019 | O42: 1370304000 | P42: =MEI!N120 -> 1.0757474e+09 | Q42: =IFERROR(P42/O42,0) -> 0.78504288 | R42: =IFERROR(P42/M42-1,0) -> -0.037097595 | S42: =IFERROR(P42/N42-1,0) -> -0.23239033 | W42: May | X42: =SUM(AG42,AG61,X61,X80,AG80) -> 2829872927 | Y42: =SUM(AH42,AH61,Y61,Y80,AH80) -> 3334047172 | Z42: =SUM(AI42,AI61,Z61,Z80,AI80) -> 4867200000 | AA42: =AJ42+AJ61+AJ80+AA80+AA61 -> 3.2150237e+09 | AB42: =IFERROR(AA42/Z42,0) -> 0.66054891 | AC42: =IFERROR(AA42/X42-1,0) -> 0.13610178 | AD42: =IFERROR(AA42/Y42-1,0) -> -0.035699406 | AF42: May | AG42: 532910554 | AH42: 591511487 | AI42: 924768000 | AJ42: =MEI!N132 -> 6.0125485e+08 | AK42: =IFERROR(AJ42/AI42,0) -> 0.65016831 | AL42: =IFERROR(AJ42/AG42-1,0) -> 0.12824721 | AM42: =IFERROR(AJ42/AH42-1,0) -> 0.016471968
C43: Jun | D43: =SUM(M43,D62,M62,D81,M81) -> 6941152654 | E43: =SUM(N43,E62,N62,E81,N81) -> 6586130629 | F43: =SUM(O43,O62,F62,F81,O81) -> 7612800000 | G43: =SUM(P43,P62,G62,G81,P81) -> 6.8125187e+09 | H43: =IFERROR(G43/F43,0) -> 0.89487688 | I43: =IFERROR(G43/D43-1,0) -> -0.018532069 | J43: =IFERROR(G43/E43-1,0) -> 0.034373461 | L43: Jun | M43: 1459042062 | N43: 1275156287 | O43: 1370304000 | P43: =JUN!N120 -> 1.333418e+09 | Q43: =IFERROR(P43/O43,0) -> 0.97308191 | R43: =IFERROR(P43/M43-1,0) -> -0.086100344 | S43: =IFERROR(P43/N43-1,0) -> 0.045689891 | W43: Jun | X43: =SUM(AG43,AG62,X62,X81,AG81) -> 3493317464 | Y43: =SUM(AH43,AH62,Y62,Y81,AH81) -> 3035444247 | Z43: =SUM(AI43,AI62,Z62,Z81,AI81) -> 4867200000 | AA43: =AJ43+AJ62+AJ81+AA81+AA62 -> 2.8762582e+09 | AB43: =IFERROR(AA43/Z43,0) -> 0.59094719 | AC43: =IFERROR(AA43/X43-1,0) -> -0.17663992 | AD43: =IFERROR(AA43/Y43-1,0) -> -0.052442438 | AF43: Jun | AG43: 863201050 | AH43: 611544701 | AI43: 924768000 | AJ43: =JUN!N132 -> 4.5516362e+08 | AK43: =IFERROR(AJ43/AI43,0) -> 0.49219223 | AL43: =IFERROR(AJ43/AG43-1,0) -> -0.47270265 | AM43: =IFERROR(AJ43/AH43-1,0) -> -0.25571487
C44: Sem1 | D44: =SUM(D38:D43) -> 31729514975 | E44: =SUM(E38:E43) -> 35029946536 | F44: =SUM(F38:F43) -> 47580000000 | G44: =SUM(G38:G43) -> 3.6814881e+10 | H44: =IFERROR(G44/F44,0) -> 0.77374697 | I44: =IFERROR(G44/D44-1,0) -> 0.16027242 | J44: =IFERROR(G44/E44-1,0) -> 0.050954531 | L44: Sem1 | M44: =SUM(M38:M43) -> 6265829433 | N44: =SUM(N38:N43) -> 6942489571 | O44: =SUM(O38:O43) -> 8564400000 | P44: =SUM(P38:P43) -> 6.4635488e+09 | Q44: =IFERROR(P44/O44,0) -> 0.75469955 | R44: =IFERROR(P44/M44-1,0) -> 0.031555177 | S44: =IFERROR(P44/N44-1,0) -> -0.068986892 | W44: Sem1 | X44: =SUM(X38:X43) -> 17641391128 | Y44: =SUM(Y38:Y43) -> 18269754662 | Z44: =SUM(Z38:Z43) -> 30420000000 | AA44: =SUM(AA38:AA43) -> 1.7678622e+10 | AB44: =IFERROR(AA44/Z44,0) -> 0.58115128 | AC44: =IFERROR(AA44/X44-1,0) -> 0.0021104151 | AD44: =IFERROR(AA44/Y44-1,0) -> -0.032355819 | AF44: Sem1 | AG44: =SUM(AG38:AG43) -> 3780943805 | AH44: =SUM(AH38:AH43) -> 3433074538 | AI44: =SUM(AI38:AI43) -> 5779800000 | AJ44: =SUM(AJ38:AJ43) -> 3.1002692e+09 | AK44: =IFERROR(AJ44/AI44,0) -> 0.53639732 | AL44: =IFERROR(AJ44/AG44-1,0) -> -0.18002769 | AM44: =IFERROR(AJ44/AH44-1,0) -> -0.096940898
C45: Jul | D45: =SUM(M45,D64,M64,D83,M83) -> 5875679047 | E45: =SUM(N45,E64,N64,E83,N83) -> 7267894803 | F45: =SUM(O45,O64,F64,F83,O83) -> 7612800000 | G45: =SUM(P45,P64,G64,G83,P83) -> 8.0213035e+09 | H45: =IFERROR(G45/F45,0) -> 1.0536601 | I45: =IFERROR(G45/D45-1,0) -> 0.36517047 | J45: =IFERROR(G45/E45-1,0) -> 0.10366258 | L45: Jul | M45: 1190076301 | N45: 1662797322 | O45: 1370304000 | P45: =JUL!F120 -> 1.4098456e+09 | Q45: =IFERROR(P45/O45,0) -> 1.0288561 | R45: =IFERROR(P45/M45-1,0) -> 0.18466827 | S45: =IFERROR(P45/N45-1,0) -> -0.15212419 | W45: Jul | X45: =SUM(AG45,AG64,X64,X83,AG83) -> 3201449380 | Y45: =SUM(AH45,AH64,Y64,Y83,AH83) -> 3255664218 | Z45: =SUM(AI45,AI64,Z64,Z83,AI83) -> 4867200000 | AA45: =AJ45+AJ64+AJ83+AA83+AA64 -> 3.4201488e+09 | AB45: =IFERROR(AA45/Z45,0) -> 0.70269329 | AC45: =IFERROR(AA45/X45-1,0) -> 0.068312625 | AD45: =IFERROR(AA45/Y45-1,0) -> 0.050522585 | AF45: Jul | AG45: 584231271 | AH45: 623383713 | AI45: 924768000 | AJ45: =JUL!F133 -> 6.3327063e+08 | AK45: =IFERROR(AJ45/AI45,0) -> 0.68478865 | AL45: =IFERROR(AJ45/AG45-1,0) -> 0.083938259 | AM45: =IFERROR(AJ45/AH45-1,0) -> 0.015860077
C46: Aug | D46: =SUM(M46,D65,M65,D84,M84) -> 6394118075 | E46: =SUM(N46,E65,N65,E84,N84) -> 6486513254 | F46: =SUM(O46,O65,F65,F84,O84) -> 8564400000 | G46: =SUM(P46,P65,G65,G84,P84) -> 7.0612351e+09 | H46: =IFERROR(G46/F46,0) -> 0.82448685 | I46: =IFERROR(G46/D46-1,0) -> 0.10433293 | J46: =IFERROR(G46/E46-1,0) -> 0.088602591 | L46: Aug | M46: 1158539608 | N46: 1391179528 | O46: 1541592000 | P46: =AGS!F120 -> 1.027245e+09 | Q46: =IFERROR(P46/O46,0) -> 0.66635339 | R46: =IFERROR(P46/M46-1,0) -> -0.11332764 | S46: =IFERROR(P46/N46-1,0) -> -0.26160138 | W46: Aug | X46: =SUM(AG46,AG65,X65,X84,AG84) -> 3230526836 | Y46: =SUM(AH46,AH65,Y65,Y84,AH84) -> 3226286515 | Z46: =SUM(AI46,AI65,Z65,Z84,AI84) -> 5475600000 | AA46: =AJ46+AJ65+AJ84+AA84+AA65 -> 3.4021727e+09 | AB46: =IFERROR(AA46/Z46,0) -> 0.62133332 | AC46: =IFERROR(AA46/X46-1,0) -> 0.053132472 | AD46: =IFERROR(AA46/Y46-1,0) -> 0.054516608 | AF46: Aug | AG46: 619575041 | AH46: 689664909 | AI46: 1040364000 | AJ46: =AGS!F133 -> 6.3564744e+08 | AK46: =IFERROR(AJ46/AI46,0) -> 0.61098561 | AL46: =IFERROR(AJ46/AG46-1,0) -> 0.025940999 | AM46: =IFERROR(AJ46/AH46-1,0) -> -0.078324229
C47: Sep | D47: =SUM(M47,D66,M66,D85,M85) -> 6664754509 | E47: =SUM(N47,E66,N66,E85,N85) -> 6964306785 | F47: =SUM(O47,O66,F66,F85,O85) -> 7612800000 | G47: =SUM(P47,P66,G66,G85,P85) -> 5.3694706e+09 | H47: =IFERROR(G47/F47,0) -> 0.70532138 | I47: =IFERROR(G47/D47-1,0) -> -0.19434833 | J47: =IFERROR(G47/E47-1,0) -> -0.22900143 | L47: Sep | M47: 1441894421 | N47: 1216508213 | O47: 1370304000 | P47: =SEP!F120 -> 8.3573211e+08 | Q47: =IFERROR(P47/O47,0) -> 0.6098881 | R47: =IFERROR(P47/M47-1,0) -> -0.42039299 | S47: =IFERROR(P47/N47-1,0) -> -0.31300743 | W47: Sep | X47: =SUM(AG47,AG66,X66,X85,AG85) -> 3134707739 | Y47: =SUM(AH47,AH66,Y66,Y85,AH85) -> 3236898009 | Z47: =SUM(AI47,AI66,Z66,Z85,AI85) -> 4867200000 | AA47: =AJ47+AJ66+AJ85+AA85+AA66 -> 2.4023329e+09 | AB47: =IFERROR(AA47/Z47,0) -> 0.49357595 | AC47: =IFERROR(AA47/X47-1,0) -> -0.23363418 | AD47: =IFERROR(AA47/Y47-1,0) -> -0.25782868 | AF47: Sep | AG47: 667756283 | AH47: 608158267 | AI47: 924768000 | AJ47: =SEP!F133 -> 3.861777e+08 | AK47: =IFERROR(AJ47/AI47,0) -> 0.41759414 | AL47: =IFERROR(AJ47/AG47-1,0) -> -0.42167867 | AM47: =IFERROR(AJ47/AH47-1,0) -> -0.3650046
C48: Oct | D48: =SUM(M48,D67,M67,D86,M86) -> 6275099751 | E48: =SUM(N48,E67,N67,E86,N86) -> 6737105069 | F48: =SUM(O48,O67,F67,F86,O86) -> 8564400000 | G48: =SUM(P48,P67,G67,G86,P86) -> 0 | H48: =IFERROR(G48/F48,0) -> 0 | I48: =IFERROR(G48/D48-1,0) -> -1 | J48: =IFERROR(G48/E48-1,0) -> -1 | L48: Oct | M48: 1110054494 | N48: 1391856103 | O48: 1541592000 | P48: =OKT!N130 -> 0 | Q48: =IFERROR(P48/O48,0) -> 0 | R48: =IFERROR(P48/M48-1,0) -> -1 | S48: =IFERROR(P48/N48-1,0) -> -1 | W48: Oct | X48: =SUM(AG48,AG67,X67,X86,AG86) -> 3586195646 | Y48: =SUM(AH48,AH67,Y67,Y86,AH86) -> 3378889733 | Z48: =SUM(AI48,AI67,Z67,Z86,AI86) -> 5475600000 | AA48: =AJ48+AJ67+AJ86+AA86+AA67 -> 0 | AB48: =IFERROR(AA48/Z48,0) -> 0 | AC48: =IFERROR(AA48/X48-1,0) -> -1 | AD48: =IFERROR(AA48/Y48-1,0) -> -1 | AF48: Oct | AG48: 622434205 | AH48: 764712117 | AI48: 1040364000 | AJ48: =OKT!N143 -> 0 | AK48: =IFERROR(AJ48/AI48,0) -> 0 | AL48: =IFERROR(AJ48/AG48-1,0) -> -1 | AM48: =IFERROR(AJ48/AH48-1,0) -> -1
C49: Nov | D49: =SUM(M49,D68,M68,D87,M87) -> 6295450802 | E49: =SUM(N49,E68,N68,E87,N87) -> 6250912188 | F49: =SUM(O49,O68,F68,F87,O87) -> 7612800000 | G49: =SUM(P49,P68,G68,G87,P87) -> 0 | H49: =IFERROR(G49/F49,0) -> 0 | I49: =IFERROR(G49/D49-1,0) -> -1 | J49: =IFERROR(G49/E49-1,0) -> -1 | L49: Nov | M49: 1194727445 | N49: 1050415668 | O49: 1370304000 | P49: =NOV!N130 -> 0 | Q49: =IFERROR(P49/O49,0) -> 0 | R49: =IFERROR(P49/M49-1,0) -> -1 | S49: =IFERROR(P49/N49-1,0) -> -1 | W49: Nov | X49: =SUM(AG49,AG68,X68,X87,AG87) -> 3203101309 | Y49: =SUM(AH49,AH68,Y68,Y87,AH87) -> 2680663229 | Z49: =SUM(AI49,AI68,Z68,Z87,AI87) -> 4867200000 | AA49: =AJ49+AJ68+AJ87+AA87+AA68 -> 0 | AB49: =IFERROR(AA49/Z49,0) -> 0 | AC49: =IFERROR(AA49/X49-1,0) -> -1 | AD49: =IFERROR(AA49/Y49-1,0) -> -1 | AF49: Nov | AG49: 628095512 | AH49: 632969529 | AI49: 924768000 | AJ49: =NOV!N143 -> 0 | AK49: =IFERROR(AJ49/AI49,0) -> 0 | AL49: =IFERROR(AJ49/AG49-1,0) -> -1 | AM49: =IFERROR(AJ49/AH49-1,0) -> -1
C50: Dec | D50: =SUM(M50,D69,M69,D88,M88) -> 6202665216 | E50: =SUM(N50,E69,N69,E88,N88) -> 7385635587 | F50: =SUM(O50,O69,F69,F88,O88) -> 7612800000 | G50: =SUM(P50,P69,G69,G88,P88) -> 0 | H50: =IFERROR(G50/F50,0) -> 0 | I50: =IFERROR(G50/D50-1,0) -> -1 | J50: =IFERROR(G50/E50-1,0) -> -1 | L50: Dec | M50: 1265831835 | N50: 1348731032 | O50: 1370304000 | P50: 0 | Q50: =IFERROR(P50/O50,0) -> 0 | R50: =IFERROR(P50/M50-1,0) -> -1 | S50: =IFERROR(P50/N50-1,0) -> -1 | W50: Dec | X50: =SUM(AG50,AG69,X69,X88,AG88) -> 3168508121 | Y50: =SUM(AH50,AH69,Y69,Y88,AH88) -> 3501669477 | Z50: =SUM(AI50,AI69,Z69,Z88,AI88) -> 4867200000 | AA50: =AJ50+AJ69+AJ88+AA88+AA69 -> 0 | AB50: =IFERROR(AA50/Z50,0) -> 0 | AC50: =IFERROR(AA50/X50-1,0) -> -1 | AD50: =IFERROR(AA50/Y50-1,0) -> -1 | AF50: Dec | AG50: 641067945 | AH50: 955986148 | AI50: 924768000 | AJ50: 0 | AK50: =IFERROR(AJ50/AI50,0) -> 0 | AL50: =IFERROR(AJ50/AG50-1,0) -> -1 | AM50: =IFERROR(AJ50/AH50-1,0) -> -1
C51: Sem 2 | D51: =SUM(D45:D50) -> 37707767400 | E51: =SUM(E45:E50) -> 41092367686 | F51: =SUM(F45:F50) -> 47580000000 | G51: =SUM(G45:G50) -> 2.0452009e+10 | H51: =IFERROR(G51/F51,0) -> 0.42984467 | I51: =IFERROR(G51/D51-1,0) -> -0.45761813 | J51: =IFERROR(G51/E51-1,0) -> -0.50229178 | L51: Sem 2 | M51: =SUM(M45:M50) -> 7361124104 | N51: =SUM(N45:N50) -> 8061487866 | O51: =SUM(O45:O50) -> 8564400000 | P51: =SUM(P45:P50) -> 3.2728228e+09 | Q51: =IFERROR(P51/O51,0) -> 0.38214268 | R51: =IFERROR(P51/M51-1,0) -> -0.5553909 | S51: =IFERROR(P51/N51-1,0) -> -0.59401753 | W51: Sem 2 | X51: =SUM(X45:X50) -> 19524489031 | Y51: =SUM(Y45:Y50) -> 19280071181 | Z51: =SUM(Z45:Z50) -> 30420000000 | AA51: =SUM(AA45:AA50) -> 9.2246544e+09 | AB51: =IFERROR(AA51/Z51,0) -> 0.30324308 | AC51: =IFERROR(AA51/X51-1,0) -> -0.52753415 | AD51: =IFERROR(AA51/Y51-1,0) -> -0.52154459 | AF51: Sem 2 | AG51: =SUM(AG45:AG50) -> 3763160257 | AH51: =SUM(AH45:AH50) -> 4274874683 | AI51: =SUM(AI45:AI50) -> 5779800000 | AJ51: =SUM(AJ45:AJ50) -> 1.6550958e+09 | AK51: =IFERROR(AJ51/AI51,0) -> 0.28635866 | AL51: =IFERROR(AJ51/AG51-1,0) -> -0.56018462 | AM51: =IFERROR(AJ51/AH51-1,0) -> -0.61283175
C52: TOTAL YTD | D52: =D44+D51 -> 69437282375 | E52: =E44+E51 -> 76122314222 | F52: =F44+F51 -> 95160000000 | G52: =G44+G51 -> 5.726689e+10 | H52: =IFERROR(G52/F52,0) -> 0.60179582 | I52: =IFERROR(G52/D52-1,0) -> -0.17527172 | J52: =IFERROR(G52/E52-1,0) -> -0.24769904 | L52: TOTAL YTD | M52: =M44+M51 -> 13626953537 | N52: =N44+N51 -> 15003977437 | O52: =O44+O51 -> 17128800000 | P52: =P44+P51 -> 9.7363716e+09 | Q52: =IFERROR(P52/O52,0) -> 0.56842111 | R52: =IFERROR(P52/M52-1,0) -> -0.28550636 | S52: =IFERROR(P52/N52-1,0) -> -0.35108063 | W52: TOTAL YTD | X52: =X44+X51 -> 37165880159 | Y52: =Y44+Y51 -> 37549825843 | Z52: =Z44+Z51 -> 60840000000 | AA52: =AA44+AA51 -> 2.6903276e+10 | AB52: =IFERROR(AA52/Z52,0) -> 0.44219718 | AC52: =IFERROR(AA52/X52-1,0) -> -0.27612972 | AD52: =IFERROR(AA52/Y52-1,0) -> -0.28353127 | AF52: TOTAL YTD | AG52: =AG44+AG51 -> 7544104062 | AH52: =AH44+AH51 -> 7707949221 | AI52: =AI44+AI51 -> 11559600000 | AJ52: =AJ44+AJ51 -> 4.755365e+09 | AK52: =IFERROR(AJ52/AI52,0) -> 0.41137799 | AL52: =IFERROR(AJ52/AG52-1,0) -> -0.36965809 | AM52: =IFERROR(AJ52/AH52-1,0) -> -0.38305704
...

Sheet AGPs
C3: Month | D3: TEAM PENJUALAN AGPS | I3: Growth
D4: 2024 | E4: 2025 | F4: TGT 2026 | G4: 2026 | H4: ACH | I4: 26 vs 24 | J4: 26 vs 25
C5: Jan | D5: =SUM(D38,X38) -> 8907493706 | E5: =SUM(E38,Y38) -> 8609872815 | F5: =SUM(F38,Z38) -> 14040000000 | G5: =G38+AA38 -> 8.9014341e+09 | H5: =IFERROR(G5/F5,0) -> 0.63400528 | I5: =IFERROR(G5/D5-1,0) -> -0.00068027672 | J5: =IFERROR(G5/E5-1,0) -> 0.033863605
C6: Feb | D6: =SUM(D39,X39) -> 8607698312 | E6: =SUM(E39,Y39) -> 9820136776 | F6: =SUM(F39,Z39) -> 12480000000 | G6: =G39+AA39 -> 8.1885422e+09 | H6: =IFERROR(G6/F6,0) -> 0.65613319 | I6: =IFERROR(G6/D6-1,0) -> -0.048695492 | J6: =IFERROR(G6/E6-1,0) -> -0.16614785
C7: Mar | D7: =SUM(D40,X40) -> 9860523540 | E7: =SUM(E40,Y40) -> 8833097464 | F7: =SUM(F40,Z40) -> 12480000000 | G7: =G40+AA40 -> 4.5625521e+09 | H7: =IFERROR(G7/F7,0) -> 0.36558911 | I7: =IFERROR(G7/D7-1,0) -> -0.53729109 | J7: =IFERROR(G7/E7-1,0) -> -0.48347088
C8: Apr | D8: =SUM(D41,X41) -> 7054407924 | E8: =SUM(E41,Y41) -> 8657814266 | F8: =SUM(F41,Z41) -> 14040000000 | G8: =G41+AA41 -> 8.8376468e+09 | H8: =IFERROR(G8/F8,0) -> 0.62946202 | I8: =IFERROR(G8/D8-1,0) -> 0.25278363 | J8: =IFERROR(G8/E8-1,0) -> 0.020771122
C9: May | D9: =SUM(D42,X42) -> 9188854012 | E9: =SUM(E42,Y42) -> 9690764871 | F9: =SUM(F42,Z42) -> 12480000000 | G9: =G42+AA42 -> 6.1018458e+09 | H9: =IFERROR(G9/F9,0) -> 0.48892995 | I9: =IFERROR(G9/D9-1,0) -> -0.33595139 | J9: =IFERROR(G9/E9-1,0) -> -0.37034426
C10: Jun | D10: =SUM(D43,X43) -> 10780710579 | E10: =SUM(E43,Y43) -> 8560807623 | F10: =SUM(F43,Z43) -> 12480000000 | G10: =G43+AA43 -> 7.9828873e+09 | H10: =IFERROR(G10/F10,0) -> 0.63965443 | I10: =IFERROR(G10/D10-1,0) -> -0.25952123 | J10: =IFERROR(G10/E10-1,0) -> -0.067507683
C11: Sem1 | D11: =SUM(D5:D10) -> 54399688073 | E11: =SUM(E5:E10) -> 54172493815 | F11: =SUM(F5:F10) -> 78000000000 | G11: =SUM(G5:G10) -> 4.4574908e+10 | H11: =IFERROR(G11/F11,0) -> 0.57147318 | I11: =IFERROR(G11/D11-1,0) -> -0.1806036 | J11: =IFERROR(G11/E11-1,0) -> -0.17716713
C12: Jul | D12: =SUM(D45,X45) -> 9997397610 | E12: =SUM(E45,Y45) -> 9137701609 | F12: =SUM(F45,Z45) -> 12480000000 | G12: =G45+AA45 -> 9.4377576e+09 | H12: =IFERROR(G12/F12,0) -> 0.75623058 | I12: =IFERROR(G12/D12-1,0) -> -0.055978567 | J12: =IFERROR(G12/E12-1,0) -> 0.032837142
C13: Aug | D13: =SUM(D46,X46) -> 9828778371 | E13: =SUM(E46,Y46) -> 9479393349 | F13: =SUM(F46,Z46) -> 14040000000 | G13: =G46+AA46 -> 7.139499e+09 | H13: =IFERROR(G13/F13,0) -> 0.50851132 | I13: =IFERROR(G13/D13-1,0) -> -0.27361278 | J13: =IFERROR(G13/E13-1,0) -> -0.2468401
C14: Sep | D14: =SUM(D47,X47) -> 9533812429 | E14: =SUM(E47,Y47) -> 8956461906 | F14: =SUM(F47,Z47) -> 12480000000 | G14: =G47+AA47 -> 6.412417e+09 | H14: =IFERROR(G14/F14,0) -> 0.51381547 | I14: =IFERROR(G14/D14-1,0) -> -0.32740264 | J14: =IFERROR(G14/E14-1,0) -> -0.28404574
C15: Oct | D15: =SUM(D48,X48) -> 10100089797 | E15: =SUM(E48,Y48) -> 8532767821 | F15: =SUM(F48,Z48) -> 14040000000 | G15: =G48+AA48 -> 0 | H15: =IFERROR(G15/F15,0) -> 0 | I15: =IFERROR(G15/D15-1,0) -> -1 | J15: =IFERROR(G15/E15-1,0) -> -1
C16: Nov | D16: =SUM(D49,X49) -> 9462732809 | E16: =SUM(E49,Y49) -> 8088621105 | F16: =SUM(F49,Z49) -> 12480000000 | G16: =G49+AA49 -> 0 | H16: =IFERROR(G16/F16,0) -> 0 | I16: =IFERROR(G16/D16-1,0) -> -1 | J16: =IFERROR(G16/E16-1,0) -> -1
C17: Dec | D17: =SUM(D50,X50) -> 9652545896 | E17: =SUM(E50,Y50) -> 8204092690 | F17: =SUM(F50,Z50) -> 12480000000 | G17: =G50+AA50 -> 0 | H17: =IFERROR(G17/F17,0) -> 0 | I17: =IFERROR(G17/D17-1,0) -> -1 | J17: =IFERROR(G17/E17-1,0) -> -1
C18: Sem 2 | D18: =SUM(D12:D17) -> 58575356912 | E18: =SUM(E12:E17) -> 52399038480 | F18: =SUM(F12:F17) -> 78000000000 | G18: =SUM(G12:G17) -> 2.2989674e+10 | H18: =IFERROR(G18/F18,0) -> 0.29473941 | I18: =IFERROR(G18/D18-1,0) -> -0.6075197 | J18: =IFERROR(G18/E18-1,0) -> -0.56125772
C19: TOTAL YTD | D19: =D11+D18 -> 112975044985 | E19: =E11+E18 -> 106571532295 | F19: =F11+F18 -> 156000000000 | G19: =G11+G18 -> 6.7564582e+10 | H19: =IFERROR(G19/F19,0) -> 0.43310629 | I19: =IFERROR(G19/D19-1,0) -> -0.40195127 | J19: =IFERROR(G19/E19-1,0) -> -0.3660166
C20: AVG YTD | D20: =IFERROR(AVERAGE(D5:D10,D12:D17),0) -> 9.4145871e+09 | E20: =IFERROR(AVERAGE(E5:E10,E12:E17),0) -> 8.880961e+09 | F20: =IFERROR(AVERAGE(F5:F10,F12:F17),0) -> 13000000000 | G20: =IFERROR(AVERAGE(G5:G10,G12:G17),0) -> 5.6303818e+09 | H20: =IFERROR(G20/F20,0) -> 0.43310629 | I20: =IFERROR(G20/D20-1,0) -> -0.40195127 | J20: =IFERROR(G20/E20-1,0) -> -0.3660166
C22: 2024 -2025 | G22: ACH 2026 vs TGT 2026
C24: =E19-D19 -> -6403512690
G25: =G19-F19 -> -8.8435418e+10
C26: 2025 -2026
C28: =G19-E19 -> -3.900695e+10
G29: TANDA TANGAN SCM
C36: Month | D36: AGPS BJB | I36: Growth | L36: Month | M36: BANTEN - BEKASI | P36: FERDIAN | R36: Growth | W36: Month | X36: AGPS JJB | AC36: Growth | AF36: Month | AG36: JAKARTA BAT - PUS | AJ36: AGUSTIAN | AL36: Growth
D37: 2024 | E37: 2025 | F37: TGT 2026 | G37: 2026 | H37: ACH | I37: 26 vs 24 | J37: 26 vs 25 | M37: 2024 | N37: 2025 | O37: TGT 2026 | P37: 2026 | Q37: ACH | R37: 26 vs 24 | S37: 26 vs 25 | X37: 2024 | Y37: 2025 | Z37: TGT 2026 | AA37: 2026 | AB37: ACH | AC37: 26 vs 24 | AD37: 26 vs 25 | AG37: 2024 | AH37: 2025 | AI37: TGT 2026 | AJ37: 2026 | AK37: ACH | AL37: 26 vs 24 | AM37: 26 vs 25
C38: Jan | D38: =SUM(M38,M57,D57,D76,M76) -> 4931480813 | E38: =SUM(N38,N57,E57,E76,N76) -> 5415014037 | F38: =SUM(O38,O57,F57,F76,O76) -> 8424000000 | G38: =P38+P57+P76+G76+G57 -> 5.2709658e+09 | H38: =IFERROR(G38/F38,0) -> 0.62570819 | I38: =IFERROR(G38/D38-1,0) -> 0.068840375 | J38: =IFERROR(G38/E38-1,0) -> -0.026601636 | L38: Jan | M38: 836820454 | N38: 983046169 | O38: 1263600000 | P38: =JAN!AB120 -> 7.3328271e+08 | Q38: =IFERROR(P38/O38,0) -> 0.58031237 | R38: =IFERROR(P38/M38-1,0) -> -0.12372755 | S38: =IFERROR(P38/N38-1,0) -> -0.25407094 | W38: Jan | X38: =SUM(AG38,AG57,X57,X76,AG76) -> 3976012893 | Y38: =SUM(AH38,AH57,Y57,Y76,AH76) -> 3194858778 | Z38: =SUM(AI38,Z57,AI57,Z76,AI76) -> 5616000000 | AA38: =AJ38+AJ57+AJ76+AA76+AA57 -> 3.6304683e+09 | AB38: =IFERROR(AA38/Z38,0) -> 0.64645092 | AC38: =IFERROR(AA38/X38-1,0) -> -0.086907301 | AD38: =IFERROR(AA38/Y38-1,0) -> 0.13634705 | AF38: Jan | AG38: 941001152 | AH38: 934369647 | AI38: 1291680000 | AJ38: =JAN!AB132 -> 1.035201e+09 | AK38: =IFERROR(AJ38/AI38,0) -> 0.80143764 | AL38: =IFERROR(AJ38/AG38-1,0) -> 0.10010596 | AM38: =IFERROR(AJ38/AH38-1,0) -> 0.10791374
C39: Feb | D39: =SUM(M39,M58,D58,D77,M77) -> 5054407322 | E39: =SUM(N39,N58,E58,E77,N77) -> 6207347191 | F39: =SUM(O39,O58,F58,F77,O77) -> 7488000000 | G39: =P39+P58+P77+G77+G58 -> 4.8824808e+09 | H39: =IFERROR(G39/F39,0) -> 0.6520407 | I39: =IFERROR(G39/D39-1,0) -> -0.03401517 | J39: =IFERROR(G39/E39-1,0) -> -0.2134352 | L39: Feb | M39: 975201426 | N39: 1165741463 | O39: 1123200000 | P39: =FEB!AB120 -> 6.8005156e+08 | Q39: =IFERROR(P39/O39,0) -> 0.60545901 | R39: =IFERROR(P39/M39-1,0) -> -0.30265528 | S39: =IFERROR(P39/N39-1,0) -> -0.41663603 | W39: Feb | X39: =SUM(AG39,AG58,X58,X77,AG77) -> 3553290990 | Y39: =SUM(AH39,AH58,Y58,Y77,AH77) -> 3612789585 | Z39: =SUM(AI39,Z58,AI58,Z77,AI77) -> 4992000000 | AA39: =AJ39+AJ58+AJ77+AA77+AA58 -> 3.3060614e+09 | AB39: =IFERROR(AA39/Z39,0) -> 0.66227192 | AC39: =IFERROR(AA39/X39-1,0) -> -0.069577633 | AD39: =IFERROR(AA39/Y39-1,0) -> -0.084900646 | AF39: Feb | AG39: 797035043 | AH39: 1070224283 | AI39: 1148160000 | AJ39: =FEB!AB132 -> 8.5096294e+08 | AK39: =IFERROR(AJ39/AI39,0) -> 0.74115362 | AL39: =IFERROR(AJ39/AG39-1,0) -> 0.067660637 | AM39: =IFERROR(AJ39/AH39-1,0) -> -0.2048742
